package ch26_Exception

fun main() {
    throw Exception("ERROR!")
}